Workbook
Name Slicer_Category: #N/A
Name Slicer_Customer_Segment: #N/A
Name Slicer_Region: #N/A

Sheet Analyze
A3: Sum of Revenue | B3: Sum of Profit | C3: Sum of Expenses | D3: Sum of Profit Margin
A4: 53965575 | B4: 20493529 | C4: 33472046 | D4: 23902.485
F5: Row Labels | G5: Total Revenue | H5: Total Profit
A6: Row Labels | B6: Sum of Revenue | C6: Sum of Profit | F6: Jan | G6: 4345545 | H6: 1424924
A7: Jan | B7: 4345545 | C7: 1424924 | F7: Feb | G7: 3855806 | H7: 1375936
A8: Feb | B8: 3855806 | C8: 1375936 | F8: Mar | G8: 4507639 | H8: 1778613
A9: Mar | B9: 4507639 | C9: 1778613 | F9: Apr | G9: 5238960 | H9: 2021789
A10: Apr | B10: 5238960 | C10: 2021789 | F10: May | G10: 4795117 | H10: 1720264
A11: May | B11: 4795117 | C11: 1720264 | F11: Jun | G11: 4291764 | H11: 1665183
A12: Jun | B12: 4291764 | C12: 1665183 | F12: Jul | G12: 4391880 | H12: 1449364
A13: Jul | B13: 4391880 | C13: 1449364 | F13: Aug | G13: 4403384 | H13: 1795133
A14: Aug | B14: 4403384 | C14: 1795133 | F14: Sep | G14: 4530455 | H14: 1735142
A15: Sep | B15: 4530455 | C15: 1735142 | F15: Oct | G15: 4185683 | H15: 1644591
A16: Oct | B16: 4185683 | C16: 1644591 | F16: Nov | G16: 4487589 | H16: 1858217
A17: Nov | B17: 4487589 | C17: 1858217 | F17: Dec | G17: 4931753 | H17: 2024373
A18: Dec | B18: 4931753 | C18: 2024373 | F18: Grand Total | G18: 53965575 | H18: 20493529
A19: Grand Total | B19: 53965575 | C19: 20493529
A21: Row Labels | B21: Sum of Revenue | D21: Row Labels | E21: Sum of Revenue
A22: HR | B22: 5399448 | D22: HR | E22: 5399448
A23: Marketing | B23: 8755912 | D23: Marketing | E23: 8755912
A24: Operations | B24: 7058076 | D24: Operations | E24: 7058076
A25: R&D | B25: 22711986 | D25: R&D | E25: 22711986
A26: Sales | B26: 10040153 | D26: Sales | E26: 10040153
A27: Grand Total | B27: 53965575 | D27: Grand Total | E27: 53965575
A29: Row Labels | B29: Sum of Profit
A30: Clothing | B30: 2924461
A31: Electronics | B31: 3782643
A32: Furniture | B32: 2171890
A33: Healthcare | B33: 8548972
A34: Software | B34: 3065563
A35: Grand Total | B35: 20493529
A37: Row Labels | B37: Sum of Revenue | E37: Sum of Profit
A38: Africa | B38: 22323937 | D38: Clothing | E38: 2924461
A39: Asia-Pacific | B39: 6601298 | D39: Electronics | E39: 3782643
A40: Europe | B40: 8659076 | D40: Furniture | E40: 2171890
A41: North America | B41: 10866328 | D41: Healthcare | E41: 8548972
A42: South America | B42: 5514936 | D42: Software | E42: 3065563
A43: Grand Total | B43: 53965575 | D43: Grand Total | E43: 20493529
A45: Row Labels | B45: Sum of Revenue
A46: B2B | B46: 12946988
...

Sheet Dashboard
A2: Filters
C14: Revenue and Profit Monthly
C15: Month | D15: Revenue | E15: Profit
C16: =Analyze!A7 -> Jan | D16: =Analyze!B7 -> 4345545 | E16: =Analyze!C7 -> 1424924
C17: =Analyze!A8 -> Feb | D17: =Analyze!B8 -> 3855806 | E17: =Analyze!C8 -> 1375936
C18: =Analyze!A9 -> Mar | D18: =Analyze!B9 -> 4507639 | E18: =Analyze!C9 -> 1778613
C19: =Analyze!A10 -> Apr | D19: =Analyze!B10 -> 5238960 | E19: =Analyze!C10 -> 2021789
C20: =Analyze!A11 -> May | D20: =Analyze!B11 -> 4795117 | E20: =Analyze!C11 -> 1720264
C21: =Analyze!A12 -> Jun | D21: =Analyze!B12 -> 4291764 | E21: =Analyze!C12 -> 1665183
C22: =Analyze!A13 -> Jul | D22: =Analyze!B13 -> 4391880 | E22: =Analyze!C13 -> 1449364
C23: =Analyze!A14 -> Aug | D23: =Analyze!B14 -> 4403384 | E23: =Analyze!C14 -> 1795133
C24: =Analyze!A15 -> Sep | D24: =Analyze!B15 -> 4530455 | E24: =Analyze!C15 -> 1735142
C25: =Analyze!A16 -> Oct | D25: =Analyze!B16 -> 4185683 | E25: =Analyze!C16 -> 1644591
C26: =Analyze!A17 -> Nov | D26: =Analyze!B17 -> 4487589 | E26: =Analyze!C17 -> 1858217
C27: =Analyze!A18 -> Dec | D27: =Analyze!B18 -> 4931753 | E27: =Analyze!C18 -> 2024373
C28: =Analyze!A19 -> Grand Total | D28: =Analyze!B19 -> 53965575 | E28: =Analyze!C19 -> 20493529
